<mujoco model="humanoid">
  <compiler angle="radian" meshdir="../meshes/"/>

  <asset>
    <material name="matplane" reflectance="0." texture="texplane" texrepeat="1 1" texuniform="true"/>
    <material name="matplane2" reflectance="0.1" texture="texplane2" texrepeat="1 1" texuniform="true"/>
    <texture name="texplane" type="2d" builtin="checker" rgb1=".2 .3 .4" rgb2=".1 0.15 0.2"
          width="512" height="512" mark="cross" markrgb=".8 .8 .8"/>
    <texture name="texplane2" type="2d" builtin="checker" rgb1="1 0.3137 0.1843" rgb2="0.0 0.30196 0.38039"
          width="512" height="512" mark="cross" markrgb=".8 .8 .8"/>

    <mesh name="pelvis" file="pelvis.STL"/>
    <mesh name="hip_roll_l_link" file="hip_roll_l_link.STL"/>
    <mesh name="hip_pitch_l_link" file="hip_pitch_l_link.STL"/>
    <mesh name="hip_yaw_l_link" file="hip_yaw_l_link.STL"/>
    <mesh name="knee_pitch_l_link" file="knee_pitch_l_link.STL"/>
    <mesh name="ankle_pitch_l_link" file="ankle_pitch_l_link.STL"/>
    <mesh name="ankle_roll_l_link" file="ankle_roll_l_link.STL"/>
    <mesh name="hip_roll_r_link" file="hip_roll_r_link.STL"/>
    <mesh name="hip_pitch_r_link" file="hip_pitch_r_link.STL"/>
    <mesh name="hip_yaw_r_link" file="hip_yaw_r_link.STL"/>
    <mesh name="knee_pitch_r_link" file="knee_pitch_r_link.STL"/>
    <mesh name="ankle_pitch_r_link" file="ankle_pitch_r_link.STL"/>
    <mesh name="ankle_roll_r_link" file="ankle_roll_r_link.STL"/>
    <mesh name="shoulder_pitch_l_link" file="shoulder_pitch_l_link.STL"/>
    <mesh name="shoulder_roll_l_link" file="shoulder_roll_l_link.STL"/>
    <mesh name="shoulder_yaw_l_link" file="shoulder_yaw_l_link.STL"/>
    <mesh name="elbow_pitch_l_link" file="elbow_pitch_l_link.STL"/>
    <mesh name="shoulder_pitch_r_link" file="shoulder_pitch_r_link.STL"/>
    <mesh name="shoulder_roll_r_link" file="shoulder_roll_r_link.STL"/>
    <mesh name="shoulder_yaw_r_link" content_type="model/stl" file="shoulder_yaw_r_link.STL"/>
    <mesh name="elbow_pitch_r_link" file="elbow_pitch_r_link.STL"/>
  </asset>

  <worldbody>
    <light directional="true" diffuse=".4 .4 .4" specular="0.1 0.1 0.1" pos="0 0 5.0" dir="0 0 -1" castshadow="false"/>
    <light directional="true" diffuse=".6 .6 .6" specular="0.2 0.2 0.2" pos="0 0 4" dir="0 0 -1"/>
    <geom name="ground" type="plane" size="10 10 0.01" pos="0.0 0 0" quat="1 0 0 0" material="matplane"/>
    <body name="pelvis">
      <inertial pos="-0.000641 0.000723 -0.074769" quat="1.0 0 0 0" mass="6.09461" diaginertia="0.0295763 0.0281052 0.0185115"/>
      <joint name="dummy_to_base_link" type="free" limited="false" actuatorfrclimited="false"/>
      <geom type="mesh" contype="0" conaffinity="0" group="1" density="0" rgba="0.752941 0.752941 0.752941 1" mesh="pelvis"/>
      <geom type="mesh" rgba="0.752941 0.752941 0.752941 1" mesh="pelvis"/>
      <body name="hip_roll_l_link" pos="0 0.028 -0.0857">
        <inertial pos="-0.001848 0.055849 -0.036017" quat="0.242041 0.661501 0.270146 0.656394" mass="0.672983" diaginertia="0.0035288 0.00296741 0.00101678"/>
        <joint name="hip_roll_l_joint" pos="0 0 0" axis="1 0 0" range="-0.79 0.79" actuatorfrcrange="-180 180"/>
        <geom type="mesh" contype="0" conaffinity="0" group="1" density="0" rgba="0.752941 0.752941 0.752941 1" mesh="hip_roll_l_link"/>
        <geom type="mesh" rgba="0.752941 0.752941 0.752941 1" mesh="hip_roll_l_link"/>
        <body name="hip_pitch_l_link" pos="0 0.122 -0.046">
          <inertial pos="0.001081 -8.8e-05 -0.013133" quat="0.703908 -0.0464278 -0.0604083 0.706193" mass="3.95191" diaginertia="0.0155995 0.0108766 0.00930186"/>
          <joint name="hip_pitch_l_joint" pos="0 0 0" axis="0 1 0" range="-2.79 2.09" actuatorfrcrange="-300 300"/>
          <geom type="mesh" contype="0" conaffinity="0" group="1" density="0" rgba="0.752941 0.752941 0.752941 1" mesh="hip_pitch_l_link"/>
          <geom type="mesh" rgba="0.752941 0.752941 0.752941 1" mesh="hip_pitch_l_link"/>
          <body name="hip_yaw_l_link" pos="0 -0.00015 -0.0987">
            <inertial pos="0.004102 -0.006542 -0.121068" quat="0.685682 -0.0129439 0.0149542 0.727633" mass="6.6708" diaginertia="0.0533758 0.0495596 0.0178685"/>
            <joint name="hip_yaw_l_joint" pos="0 0 0" axis="0 0 1" range="-1.04 1.04" actuatorfrcrange="-180 180"/>
            <geom type="mesh" contype="0" conaffinity="0" group="1" density="0" rgba="0.752941 0.752941 0.752941 1" mesh="hip_yaw_l_link"/>
            <geom type="mesh" rgba="0.752941 0.752941 0.752941 1" mesh="hip_yaw_l_link"/>
            <body name="knee_pitch_l_link" pos="0 0.00010715 -0.3013">
              <inertial pos="0.00018 0.001915 -0.178653" quat="0.741662 0.0200239 0.0403837 0.669257" mass="2.31269" diaginertia="0.0309319 0.0304477 0.00269639"/>
              <joint name="knee_pitch_l_joint" pos="0 0 0" axis="0 1 0" range="0 2.39" actuatorfrcrange="-300 300"/>
              <geom type="mesh" contype="0" conaffinity="0" group="1" density="0" rgba="0.752941 0.752941 0.752941 1" mesh="knee_pitch_l_link"/>
              <geom type="mesh" rgba="0.752941 0.752941 0.752941 1" mesh="knee_pitch_l_link"/>
              <body name="ankle_pitch_l_link" pos="0 0 -0.4">
                <inertial pos="0 0 0" quat="0.5 0.5 -0.5 0.5" mass="0.111609" diaginertia="3.2e-05 1.8e-05 1.8e-05"/>
                <joint name="ankle_pitch_l_joint" pos="0 0 0" axis="0 1 0" range="-1.22 0.5236" actuatorfrcrange="-60 60"/>
                <geom type="mesh" contype="0" conaffinity="0" group="1" density="0" rgba="0.752941 0.752941 0.752941 1" mesh="ankle_pitch_l_link"/>
                <geom type="mesh" rgba="0.752941 0.752941 0.752941 1" mesh="ankle_pitch_l_link"/>
                <body name="ankle_roll_l_link">
                  <inertial pos="0.021235 0 -0.032883" quat="0 0.747289 0 0.6645" mass="1.01738" diaginertia="0.0063132 0.006055 0.000954799"/>
                  <joint name="ankle_roll_l_joint" pos="0 0 0" axis="1 0 0" range="-0.4363 0.4363" actuatorfrcrange="-30 30"/>
                  <geom type="mesh" contype="0" conaffinity="0" group="1" density="0" rgba="0.752941 0.752941 0.752941 1" mesh="ankle_roll_l_link"/>
                  <geom type="mesh" rgba="0.752941 0.752941 0.752941 1" mesh="ankle_roll_l_link"/>
                </body>
              </body>
            </body>
          </body>
        </body>
      </body>
      <body name="hip_roll_r_link" pos="0 -0.028 -0.0857">
        <inertial pos="-0.001848 -0.055849 -0.036017" quat="-0.242041 0.661501 -0.270146 0.656394" mass="0.672983" diaginertia="0.0035288 0.00296741 0.00101678"/>
        <joint name="hip_roll_r_joint" pos="0 0 0" axis="1 0 0" range="-0.79 0.79" actuatorfrcrange="-180 180"/>
        <geom type="mesh" contype="0" conaffinity="0" group="1" density="0" rgba="0.752941 0.752941 0.752941 1" mesh="hip_roll_r_link"/>
        <geom type="mesh" rgba="0.752941 0.752941 0.752941 1" mesh="hip_roll_r_link"/>
        <body name="hip_pitch_r_link" pos="0 -0.122 -0.046">
          <inertial pos="0.001081 8.8e-05 -0.013133" quat="0.706193 -0.0604083 -0.0464278 0.703908" mass="3.95191" diaginertia="0.0155995 0.0108766 0.00930186"/>
          <joint name="hip_pitch_r_joint" pos="0 0 0" axis="0 1 0" range="-2.79 2.09" actuatorfrcrange="-300 300"/>
          <geom type="mesh" contype="0" conaffinity="0" group="1" density="0" rgba="0.752941 0.752941 0.752941 1" mesh="hip_pitch_r_link"/>
          <geom type="mesh" rgba="0.752941 0.752941 0.752941 1" mesh="hip_pitch_r_link"/>
          <body name="hip_yaw_r_link" pos="0 0 -0.0987">
            <inertial pos="0.004102 0.006542 -0.121068" quat="0.727633 0.0149542 -0.0129439 0.685682" mass="6.6708" diaginertia="0.0533758 0.0495596 0.0178685"/>
            <joint name="hip_yaw_r_joint" pos="0 0 0" axis="0 0 1" range="-1.04 1.04" actuatorfrcrange="-180 180"/>
            <geom type="mesh" contype="0" conaffinity="0" group="1" density="0" rgba="0.752941 0.752941 0.752941 1" mesh="hip_yaw_r_link"/>
            <geom type="mesh" rgba="0.752941 0.752941 0.752941 1" mesh="hip_yaw_r_link"/>
            <body name="knee_pitch_r_link" pos="0 0.00035002 -0.3013">
              <inertial pos="0.00018 -0.001915 -0.178653" quat="0.669257 0.0403837 0.0200239 0.741662" mass="2.31269" diaginertia="0.0309319 0.0304477 0.00269639"/>
              <joint name="knee_pitch_r_joint" pos="0 0 0" axis="0 1 0" range="0 2.39" actuatorfrcrange="-300 300"/>
              <geom type="mesh" contype="0" conaffinity="0" group="1" density="0" rgba="0.752941 0.752941 0.752941 1" mesh="knee_pitch_r_link"/>
              <geom type="mesh" rgba="0.752941 0.752941 0.752941 1" mesh="knee_pitch_r_link"/>
              <body name="ankle_pitch_r_link" pos="0 0.00074981 -0.4">
                <inertial pos="0 0 0" quat="0.5 0.5 -0.5 0.5" mass="0.111609" diaginertia="3.2e-05 1.8e-05 1.8e-05"/>
                <joint name="ankle_pitch_r_joint" pos="0 0 0" axis="0 1 0" range="-1.22 0.5236" actuatorfrcrange="-60 60"/>
                <geom type="mesh" contype="0" conaffinity="0" group="1" density="0" rgba="0.752941 0.752941 0.752941 1" mesh="ankle_pitch_r_link"/>
                <geom type="mesh" rgba="0.752941 0.752941 0.752941 1" mesh="ankle_pitch_r_link"/>
                <body name="ankle_roll_r_link">
                  <inertial pos="0.021235 0 -0.032883" quat="0 0.747289 0 0.6645" mass="1.01738" diaginertia="0.0063132 0.006055 0.000954799"/>
                  <joint name="ankle_roll_r_joint" pos="0 0 0" axis="1 0 0" range="-0.4363 0.4363" actuatorfrcrange="-30 30"/>
                  <geom type="mesh" contype="0" conaffinity="0" group="1" density="0" rgba="0.752941 0.752941 0.752941 1" mesh="ankle_roll_r_link"/>
                  <geom type="mesh" rgba="0.752941 0.752941 0.752941 1" mesh="ankle_roll_r_link"/>
                </body>
              </body>
            </body>
          </body>
        </body>
      </body>
      <body name="shoulder_pitch_l_link" pos="0 0.14034 0.37677" quat="0.999048 0.0436192 0 0">
        <inertial pos="0.006486 0.068343 0.000219" quat="0.591341 0.393139 -0.57492 0.406478" mass="0.469057" diaginertia="0.000468095 0.000406799 0.000362107"/>
        <joint name="shoulder_pitch_l_joint" pos="0 0 0" axis="0 1 0" range="-2.96 2.96" actuatorfrcrange="-52.5 52.5"/>
        <geom type="mesh" contype="0" conaffinity="0" group="1" density="0" rgba="0.752941 0.752941 0.752941 1" mesh="shoulder_pitch_l_link"/>
        <geom type="mesh" rgba="0.752941 0.752941 0.752941 1" mesh="shoulder_pitch_l_link"/>
        <body name="shoulder_roll_l_link" pos="0 0.073 0">
          <inertial pos="-0.000165 0.001557 -0.049098" quat="0.706276 -0.0203759 0.0112258 0.707554" mass="0.298029" diaginertia="0.00099885 0.000881052 0.000573098"/>
          <joint name="shoulder_roll_l_joint" pos="0 0 0" axis="1 0 0" range="-0.2618 3.4" actuatorfrcrange="-52.5 52.5"/>
          <geom type="mesh" contype="0" conaffinity="0" group="1" density="0" rgba="0.752941 0.752941 0.752941 1" mesh="shoulder_roll_l_link"/>
          <geom type="mesh" rgba="0.752941 0.752941 0.752941 1" mesh="shoulder_roll_l_link"/>
          <body name="shoulder_yaw_l_link" pos="0 0 -0.13">
            <inertial pos="0.00809 -0.00102 -0.082881" quat="0.996315 -0.0129283 -0.0731393 0.0428919" mass="0.93608" diaginertia="0.0041934 0.00415703 0.000708565"/>
            <joint name="shoulder_yaw_l_joint" pos="0 0 0" axis="0 0 1" range="-2.96 2.96" actuatorfrcrange="-52.5 52.5"/>
            <geom type="mesh" contype="0" conaffinity="0" group="1" density="0" rgba="0.752941 0.752941 0.752941 1" mesh="shoulder_yaw_l_link"/>
            <geom type="mesh" rgba="0.752941 0.752941 0.752941 1" mesh="shoulder_yaw_l_link"/>
            <body name="elbow_pitch_l_link" pos="0.019998 0 -0.15">
              <inertial pos="-0.019072 3.1e-05 -0.195441" quat="0.999198 0.00319299 0.00605842 0.0394438" mass="0.553799" diaginertia="0.00848749 0.00844401 0.000474499"/>
              <joint name="elbow_pitch_l_joint" pos="0 0 0" axis="0 1 0" range="-2.61 0.261" actuatorfrcrange="-52.5 52.5"/>
              <geom type="mesh" contype="0" conaffinity="0" group="1" density="0" rgba="0.752941 0.752941 0.752941 1" mesh="elbow_pitch_l_link"/>
              <geom type="mesh" rgba="0.752941 0.752941 0.752941 1" mesh="elbow_pitch_l_link"/>
            </body>
          </body>
        </body>
      </body>
      <body name="shoulder_pitch_r_link" pos="0 -0.14034 0.37677" quat="0.999048 -0.0436192 0 0">
        <inertial pos="0.006486 -0.068343 0.000219" quat="0.393139 0.591341 -0.406478 0.57492" mass="0.469057" diaginertia="0.000468095 0.000406799 0.000362107"/>
        <joint name="shoulder_pitch_r_joint" pos="0 0 0" axis="0 1 0" range="-2.96 2.96" actuatorfrcrange="-52.5 52.5"/>
        <geom type="mesh" contype="0" conaffinity="0" group="1" density="0" rgba="0.752941 0.752941 0.752941 1" mesh="shoulder_pitch_r_link"/>
        <geom type="mesh" rgba="0.752941 0.752941 0.752941 1" mesh="shoulder_pitch_r_link"/>
        <body name="shoulder_roll_r_link" pos="0 -0.073 0">
          <inertial pos="-0.000165 -0.001557 -0.049098" quat="0.707554 0.0112258 -0.0203759 0.706276" mass="0.298029" diaginertia="0.00099885 0.000881052 0.000573098"/>
          <joint name="shoulder_roll_r_joint" pos="0 0 0" axis="1 0 0" range="-3.4 0.2618" actuatorfrcrange="-52.5 52.5"/>
          <geom type="mesh" contype="0" conaffinity="0" group="1" density="0" rgba="0.752941 0.752941 0.752941 1" mesh="shoulder_roll_r_link"/>
          <geom type="mesh" rgba="0.752941 0.752941 0.752941 1" mesh="shoulder_roll_r_link"/>
          <body name="shoulder_yaw_r_link" pos="0 0 -0.13">
            <inertial pos="0.00809 0.00102 -0.082881" quat="0.996315 0.0129283 -0.0731393 -0.0428919" mass="0.93608" diaginertia="0.0041934 0.00415703 0.000708565"/>
            <joint name="shoulder_yaw_r_joint" pos="0 0 0" axis="0 0 1" range="-2.96 2.96" actuatorfrcrange="-52.5 52.5"/>
            <geom type="mesh" contype="0" conaffinity="0" group="1" density="0" rgba="0.752941 0.752941 0.752941 1" mesh="shoulder_yaw_r_link"/>
            <geom type="mesh" rgba="0.752941 0.752941 0.752941 1" mesh="shoulder_yaw_r_link"/>
            <body name="elbow_pitch_r_link" pos="0.020003 0 -0.15">
              <inertial pos="-0.019072 -3.1e-05 -0.195441" quat="0.999198 -0.00319299 0.00605842 -0.0394438" mass="0.553799" diaginertia="0.00848749 0.00844401 0.000474499"/>
              <joint name="elbow_pitch_r_joint" pos="0 0 0" axis="0 1 0" range="-2.61 0.261" actuatorfrcrange="-52.5 52.5"/>
              <geom type="mesh" contype="0" conaffinity="0" group="1" density="0" rgba="0.752941 0.752941 0.752941 1" mesh="elbow_pitch_r_link"/>
              <geom type="mesh" rgba="0.752941 0.752941 0.752941 1" mesh="elbow_pitch_r_link"/>
            </body>
          </body>
        </body>
      </body>
    </body>
  </worldbody>
</mujoco>
